2019-02-07 21:23:29,525 django.request WARNING  Not Found: /api/employee/my-company/
2019-02-07 23:54:38,727 django.request WARNING  Not Found: /api//company/undefined/
2019-02-07 23:54:43,567 django.request WARNING  Not Found: /api//company/undefined/
2019-02-08 06:10:46,660 django.request WARNING  Not Found: /favicon.ico
2019-02-08 07:15:31,125 django.request WARNING  Not Found: /
2019-02-08 07:15:31,594 django.request WARNING  Not Found: /favicon.ico
2019-02-08 07:22:30,609 django.request WARNING  Not Found: /api/employee/my-company/
2019-02-08 07:25:06,870 django.request WARNING  Not Found: /api//company/undefined/
2019-02-08 07:33:23,941 apps.auth.models DEBUG    reset token 53o-be6ffb2a6bc68b013a92--10
2019-02-08 09:37:14,693 apps.auth.models INFO     Verification mail send to akhileshrao19@gmail.com
2019-02-08 09:38:54,252 apps.company.models INFO     creation mail send to test@t.com
2019-02-08 09:38:55,344 apps.company.models INFO     creation mail send to akhileshrao19@gmail.com
2019-02-08 09:40:53,961 apps.company.models INFO     Invite mail send to akhileshrao19@gmail.com
2019-02-08 09:55:41,588 apps.auth.models DEBUG    reset token 53o-2a1bdf89051ef46ee7d9--1
2019-02-08 10:06:10,876 django.request ERROR    Internal Server Error: /api/company/invite-employee/
Traceback (most recent call last):
  File "/home/akhilesh/.envs/wf/local/lib/python2.7/site-packages/django/core/handlers/exception.py", line 41, in inner
    response = get_response(request)
  File "/home/akhilesh/.envs/wf/local/lib/python2.7/site-packages/django/core/handlers/base.py", line 187, in _get_response
    response = self.process_exception_by_middleware(e, request)
  File "/home/akhilesh/.envs/wf/local/lib/python2.7/site-packages/django/core/handlers/base.py", line 185, in _get_response
    response = wrapped_callback(request, *callback_args, **callback_kwargs)
  File "/home/akhilesh/.envs/wf/local/lib/python2.7/site-packages/django/views/decorators/csrf.py", line 58, in wrapped_view
    return view_func(*args, **kwargs)
  File "/home/akhilesh/.envs/wf/local/lib/python2.7/site-packages/rest_framework/viewsets.py", line 103, in view
    return self.dispatch(request, *args, **kwargs)
  File "/home/akhilesh/.envs/wf/local/lib/python2.7/site-packages/rest_framework/views.py", line 483, in dispatch
    response = self.handle_exception(exc)
  File "/home/akhilesh/.envs/wf/local/lib/python2.7/site-packages/rest_framework/views.py", line 443, in handle_exception
    self.raise_uncaught_exception(exc)
  File "/home/akhilesh/.envs/wf/local/lib/python2.7/site-packages/rest_framework/views.py", line 480, in dispatch
    response = handler(request, *args, **kwargs)
  File "/home/akhilesh/Documents/workflow_platform/apps/company/views.py", line 139, in invite_employee
    serializer.save()
  File "/home/akhilesh/.envs/wf/local/lib/python2.7/site-packages/rest_framework/serializers.py", line 214, in save
    self.instance = self.create(validated_data)
  File "/home/akhilesh/Documents/workflow_platform/apps/company/serializers.py", line 233, in create
    user = self.get_user_instance(validated_data)
  File "/home/akhilesh/Documents/workflow_platform/apps/company/serializers.py", line 229, in get_user_instance
    **user
  File "/home/akhilesh/Documents/workflow_platform/apps/auth/models.py", line 53, in create_user
    return self._create_user(email, password, **extra_fields)
  File "/home/akhilesh/Documents/workflow_platform/apps/auth/models.py", line 42, in _create_user
    user = self.model(email=email, **extra_fields)
  File "/home/akhilesh/.envs/wf/local/lib/python2.7/site-packages/django/contrib/auth/base_user.py", line 68, in __init__
    super(AbstractBaseUser, self).__init__(*args, **kwargs)
  File "/home/akhilesh/.envs/wf/local/lib/python2.7/site-packages/django/db/models/base.py", line 571, in __init__
    raise TypeError("'%s' is an invalid keyword argument for this function" % list(kwargs)[0])
TypeError: 'is_admin' is an invalid keyword argument for this function
2019-02-08 10:06:51,253 apps.company.models INFO     Invite mail send to parul@pokemail.net
2019-02-08 10:08:21,079 apps.company.models INFO     Invite mail send to zigzag@pokemail.net
2019-02-08 10:09:20,614 apps.company.models INFO     Invite mail send to zigzag@pokemail.net
2019-02-08 10:12:22,999 django.request ERROR    Internal Server Error: /admin/company/usercompany/34/change/
Traceback (most recent call last):
  File "/home/akhilesh/.envs/wf/local/lib/python2.7/site-packages/django/core/handlers/exception.py", line 41, in inner
    response = get_response(request)
  File "/home/akhilesh/.envs/wf/local/lib/python2.7/site-packages/django/core/handlers/base.py", line 187, in _get_response
    response = self.process_exception_by_middleware(e, request)
  File "/home/akhilesh/.envs/wf/local/lib/python2.7/site-packages/django/core/handlers/base.py", line 185, in _get_response
    response = wrapped_callback(request, *callback_args, **callback_kwargs)
  File "/home/akhilesh/.envs/wf/local/lib/python2.7/site-packages/django/contrib/admin/options.py", line 551, in wrapper
    return self.admin_site.admin_view(view)(*args, **kwargs)
  File "/home/akhilesh/.envs/wf/local/lib/python2.7/site-packages/django/utils/decorators.py", line 149, in _wrapped_view
    response = view_func(request, *args, **kwargs)
  File "/home/akhilesh/.envs/wf/local/lib/python2.7/site-packages/django/views/decorators/cache.py", line 57, in _wrapped_view_func
    response = view_func(request, *args, **kwargs)
  File "/home/akhilesh/.envs/wf/local/lib/python2.7/site-packages/django/contrib/admin/sites.py", line 224, in inner
    return view(request, *args, **kwargs)
  File "/home/akhilesh/.envs/wf/local/lib/python2.7/site-packages/django/contrib/admin/options.py", line 1511, in change_view
    return self.changeform_view(request, object_id, form_url, extra_context)
  File "/home/akhilesh/.envs/wf/local/lib/python2.7/site-packages/django/utils/decorators.py", line 67, in _wrapper
    return bound_func(*args, **kwargs)
  File "/home/akhilesh/.envs/wf/local/lib/python2.7/site-packages/django/utils/decorators.py", line 149, in _wrapped_view
    response = view_func(request, *args, **kwargs)
  File "/home/akhilesh/.envs/wf/local/lib/python2.7/site-packages/django/utils/decorators.py", line 63, in bound_func
    return func.__get__(self, type(self))(*args2, **kwargs2)
  File "/home/akhilesh/.envs/wf/local/lib/python2.7/site-packages/django/contrib/admin/options.py", line 1408, in changeform_view
    return self._changeform_view(request, object_id, form_url, extra_context)
  File "/home/akhilesh/.envs/wf/local/lib/python2.7/site-packages/django/contrib/admin/options.py", line 1448, in _changeform_view
    self.save_model(request, new_object, form, not add)
  File "/home/akhilesh/.envs/wf/local/lib/python2.7/site-packages/django/contrib/admin/options.py", line 979, in save_model
    obj.save()
  File "/home/akhilesh/.envs/wf/local/lib/python2.7/site-packages/django/db/models/base.py", line 806, in save
    force_update=force_update, update_fields=update_fields)
  File "/home/akhilesh/.envs/wf/local/lib/python2.7/site-packages/django/db/models/base.py", line 836, in save_base
    updated = self._save_table(raw, cls, force_insert, force_update, using, update_fields)
  File "/home/akhilesh/.envs/wf/local/lib/python2.7/site-packages/django/db/models/base.py", line 903, in _save_table
    forced_update)
  File "/home/akhilesh/.envs/wf/local/lib/python2.7/site-packages/django/db/models/base.py", line 953, in _do_update
    return filtered._update(values) > 0
  File "/home/akhilesh/.envs/wf/local/lib/python2.7/site-packages/django/db/models/query.py", line 661, in _update
    return query.get_compiler(self.db).execute_sql(CURSOR)
  File "/home/akhilesh/.envs/wf/local/lib/python2.7/site-packages/django/db/models/sql/compiler.py", line 1191, in execute_sql
    cursor = super(SQLUpdateCompiler, self).execute_sql(result_type)
  File "/home/akhilesh/.envs/wf/local/lib/python2.7/site-packages/django/db/models/sql/compiler.py", line 876, in execute_sql
    cursor.execute(sql, params)
  File "/home/akhilesh/.envs/wf/local/lib/python2.7/site-packages/django/db/backends/utils.py", line 80, in execute
    return super(CursorDebugWrapper, self).execute(sql, params)
  File "/home/akhilesh/.envs/wf/local/lib/python2.7/site-packages/django/db/backends/utils.py", line 65, in execute
    return self.cursor.execute(sql, params)
  File "/home/akhilesh/.envs/wf/local/lib/python2.7/site-packages/django/db/utils.py", line 94, in __exit__
    six.reraise(dj_exc_type, dj_exc_value, traceback)
  File "/home/akhilesh/.envs/wf/local/lib/python2.7/site-packages/django/db/backends/utils.py", line 65, in execute
    return self.cursor.execute(sql, params)
IntegrityError: duplicate key value violates unique constraint "company_use_user_id_a07d1a_partial"
DETAIL:  Key (user_id, company_id)=(36, 2) already exists.

2019-02-08 10:12:44,409 django.request ERROR    Internal Server Error: /admin/company/usercompany/34/change/
Traceback (most recent call last):
  File "/home/akhilesh/.envs/wf/local/lib/python2.7/site-packages/django/core/handlers/exception.py", line 41, in inner
    response = get_response(request)
  File "/home/akhilesh/.envs/wf/local/lib/python2.7/site-packages/django/core/handlers/base.py", line 187, in _get_response
    response = self.process_exception_by_middleware(e, request)
  File "/home/akhilesh/.envs/wf/local/lib/python2.7/site-packages/django/core/handlers/base.py", line 185, in _get_response
    response = wrapped_callback(request, *callback_args, **callback_kwargs)
  File "/home/akhilesh/.envs/wf/local/lib/python2.7/site-packages/django/contrib/admin/options.py", line 551, in wrapper
    return self.admin_site.admin_view(view)(*args, **kwargs)
  File "/home/akhilesh/.envs/wf/local/lib/python2.7/site-packages/django/utils/decorators.py", line 149, in _wrapped_view
    response = view_func(request, *args, **kwargs)
  File "/home/akhilesh/.envs/wf/local/lib/python2.7/site-packages/django/views/decorators/cache.py", line 57, in _wrapped_view_func
    response = view_func(request, *args, **kwargs)
  File "/home/akhilesh/.envs/wf/local/lib/python2.7/site-packages/django/contrib/admin/sites.py", line 224, in inner
    return view(request, *args, **kwargs)
  File "/home/akhilesh/.envs/wf/local/lib/python2.7/site-packages/django/contrib/admin/options.py", line 1511, in change_view
    return self.changeform_view(request, object_id, form_url, extra_context)
  File "/home/akhilesh/.envs/wf/local/lib/python2.7/site-packages/django/utils/decorators.py", line 67, in _wrapper
    return bound_func(*args, **kwargs)
  File "/home/akhilesh/.envs/wf/local/lib/python2.7/site-packages/django/utils/decorators.py", line 149, in _wrapped_view
    response = view_func(request, *args, **kwargs)
  File "/home/akhilesh/.envs/wf/local/lib/python2.7/site-packages/django/utils/decorators.py", line 63, in bound_func
    return func.__get__(self, type(self))(*args2, **kwargs2)
  File "/home/akhilesh/.envs/wf/local/lib/python2.7/site-packages/django/contrib/admin/options.py", line 1408, in changeform_view
    return self._changeform_view(request, object_id, form_url, extra_context)
  File "/home/akhilesh/.envs/wf/local/lib/python2.7/site-packages/django/contrib/admin/options.py", line 1448, in _changeform_view
    self.save_model(request, new_object, form, not add)
  File "/home/akhilesh/.envs/wf/local/lib/python2.7/site-packages/django/contrib/admin/options.py", line 979, in save_model
    obj.save()
  File "/home/akhilesh/.envs/wf/local/lib/python2.7/site-packages/django/db/models/base.py", line 806, in save
    force_update=force_update, update_fields=update_fields)
  File "/home/akhilesh/.envs/wf/local/lib/python2.7/site-packages/django/db/models/base.py", line 836, in save_base
    updated = self._save_table(raw, cls, force_insert, force_update, using, update_fields)
  File "/home/akhilesh/.envs/wf/local/lib/python2.7/site-packages/django/db/models/base.py", line 903, in _save_table
    forced_update)
  File "/home/akhilesh/.envs/wf/local/lib/python2.7/site-packages/django/db/models/base.py", line 953, in _do_update
    return filtered._update(values) > 0
  File "/home/akhilesh/.envs/wf/local/lib/python2.7/site-packages/django/db/models/query.py", line 661, in _update
    return query.get_compiler(self.db).execute_sql(CURSOR)
  File "/home/akhilesh/.envs/wf/local/lib/python2.7/site-packages/django/db/models/sql/compiler.py", line 1191, in execute_sql
    cursor = super(SQLUpdateCompiler, self).execute_sql(result_type)
  File "/home/akhilesh/.envs/wf/local/lib/python2.7/site-packages/django/db/models/sql/compiler.py", line 876, in execute_sql
    cursor.execute(sql, params)
  File "/home/akhilesh/.envs/wf/local/lib/python2.7/site-packages/django/db/backends/utils.py", line 80, in execute
    return super(CursorDebugWrapper, self).execute(sql, params)
  File "/home/akhilesh/.envs/wf/local/lib/python2.7/site-packages/django/db/backends/utils.py", line 65, in execute
    return self.cursor.execute(sql, params)
  File "/home/akhilesh/.envs/wf/local/lib/python2.7/site-packages/django/db/utils.py", line 94, in __exit__
    six.reraise(dj_exc_type, dj_exc_value, traceback)
  File "/home/akhilesh/.envs/wf/local/lib/python2.7/site-packages/django/db/backends/utils.py", line 65, in execute
    return self.cursor.execute(sql, params)
IntegrityError: duplicate key value violates unique constraint "company_use_user_id_a07d1a_partial"
DETAIL:  Key (user_id, company_id)=(36, 2) already exists.

2019-02-08 10:28:02,132 django.request ERROR    Internal Server Error: /api/company/new-company/
Traceback (most recent call last):
  File "/home/akhilesh/.envs/wf/local/lib/python2.7/site-packages/django/core/handlers/exception.py", line 41, in inner
    response = get_response(request)
  File "/home/akhilesh/.envs/wf/local/lib/python2.7/site-packages/django/core/handlers/base.py", line 187, in _get_response
    response = self.process_exception_by_middleware(e, request)
  File "/home/akhilesh/.envs/wf/local/lib/python2.7/site-packages/django/core/handlers/base.py", line 185, in _get_response
    response = wrapped_callback(request, *callback_args, **callback_kwargs)
  File "/home/akhilesh/.envs/wf/local/lib/python2.7/site-packages/django/views/decorators/csrf.py", line 58, in wrapped_view
    return view_func(*args, **kwargs)
  File "/home/akhilesh/.envs/wf/local/lib/python2.7/site-packages/rest_framework/viewsets.py", line 103, in view
    return self.dispatch(request, *args, **kwargs)
  File "/home/akhilesh/.envs/wf/local/lib/python2.7/site-packages/rest_framework/views.py", line 483, in dispatch
    response = self.handle_exception(exc)
  File "/home/akhilesh/.envs/wf/local/lib/python2.7/site-packages/rest_framework/views.py", line 443, in handle_exception
    self.raise_uncaught_exception(exc)
  File "/home/akhilesh/.envs/wf/local/lib/python2.7/site-packages/rest_framework/views.py", line 480, in dispatch
    response = handler(request, *args, **kwargs)
  File "/home/akhilesh/Documents/workflow_platform/apps/company/views.py", line 66, in new_company
    serializer.save()
  File "/home/akhilesh/.envs/wf/local/lib/python2.7/site-packages/rest_framework/serializers.py", line 214, in save
    self.instance = self.create(validated_data)
  File "/home/akhilesh/Documents/workflow_platform/apps/company/serializers.py", line 153, in create
    company.company_create_mail()
AttributeError: 'Company' object has no attribute 'company_create_mail'
2019-02-08 10:28:52,590 apps.company.models INFO     Invite mail send to zigzag@pokemail.net
2019-02-08 10:37:16,999 apps.company.models INFO     Invite mail send to zigzag@pokemail.net
2019-02-08 10:38:36,232 apps.company.models INFO     Invite mail send to parul@pokemail.net
2019-02-08 12:03:25,487 apps.auth.models DEBUG    reset token 53o-69aabe2313d5cf9b448f--37
2019-02-08 12:08:02,461 apps.auth.serializers DEBUG    reset request for pawan.bansal@joshtechnology.com
2019-02-08 12:08:02,461 apps.auth.models DEBUG    reset token 53o-69aabe2313d5cf9b448f--37
2019-02-08 12:08:27,168 apps.auth.serializers DEBUG    reset request for pawan.bansal@joshtechnology.com
2019-02-08 12:08:27,168 apps.auth.models DEBUG    reset token 53o-69aabe2313d5cf9b448f--37
2019-02-11 08:00:50,872 django.request WARNING  Not Found: /favicon.ico
2019-02-11 09:05:18,707 django.request WARNING  Not Found: /api/
2019-02-11 09:05:21,823 django.request WARNING  Not Found: /
2019-02-11 09:08:22,239 apps.auth.serializers DEBUG    reset request for bansal.pawan96@gmail.com
2019-02-11 09:08:22,240 apps.auth.models DEBUG    reset token 53r-abc32decc4d54627c150--2
2019-02-11 09:11:45,531 django.request ERROR    Internal Server Error: /api/user/reset-password/53r-abc32decc4d54627c150--2
Traceback (most recent call last):
  File "/home/ubuntu16-jtg/Envs/env_rampup/local/lib/python2.7/site-packages/django/core/handlers/exception.py", line 41, in inner
    response = get_response(request)
  File "/home/ubuntu16-jtg/Envs/env_rampup/local/lib/python2.7/site-packages/django/utils/deprecation.py", line 138, in __call__
    response = self.process_request(request)
  File "/home/ubuntu16-jtg/Envs/env_rampup/local/lib/python2.7/site-packages/django/middleware/common.py", line 63, in process_request
    path = self.get_full_path_with_slash(request)
  File "/home/ubuntu16-jtg/Envs/env_rampup/local/lib/python2.7/site-packages/django/middleware/common.py", line 101, in get_full_path_with_slash
    'url': request.get_host() + new_path,
RuntimeError: You called this URL via POST, but the URL doesn't end in a slash and you have APPEND_SLASH set. Django can't redirect to the slash URL while maintaining POST data. Change your form to point to localhost:8000/api/user/reset-password/53r-abc32decc4d54627c150--2/ (note the trailing slash), or set APPEND_SLASH=False in your Django settings.
2019-02-11 09:14:05,726 django.request WARNING  Not Found: /api/employee/my-company/
2019-02-11 09:32:16,761 apps.auth.serializers DEBUG    reset request for akhileshrao19@gmail.com
2019-02-11 09:32:16,761 apps.auth.models DEBUG    reset token 53r-44f5dea5830c5e0bfd41--3
2019-02-11 09:50:38,652 django.request WARNING  Not Found: /api//update-company/undefined/
2019-02-11 09:51:19,199 django.request WARNING  Not Found: /api/update-company/undefined/
2019-02-11 10:34:09,513 apps.auth.serializers DEBUG    reset request for bansal.pawan96@gmail.com
2019-02-11 10:34:09,513 apps.auth.models DEBUG    reset token 53r-5b5d86b3a9dc5c190ef5--2
2019-02-11 12:34:08,988 django.request WARNING  Not Found: /profile/5dc680f8-9120-48ee-8fa9-8e7cdc13efd3-profile_pawan.png
2019-02-11 12:34:28,560 django.request WARNING  Not Found: /user/profile/5dc680f8-9120-48ee-8fa9-8e7cdc13efd3-profile_pawan.png
2019-02-11 12:41:23,190 django.request ERROR    Internal Server Error: /api/user/login/
Traceback (most recent call last):
  File "/home/ubuntu16-jtg/Envs/env_rampup/local/lib/python2.7/site-packages/django/core/handlers/exception.py", line 41, in inner
    response = get_response(request)
  File "/home/ubuntu16-jtg/Envs/env_rampup/local/lib/python2.7/site-packages/django/core/handlers/base.py", line 187, in _get_response
    response = self.process_exception_by_middleware(e, request)
  File "/home/ubuntu16-jtg/Envs/env_rampup/local/lib/python2.7/site-packages/django/core/handlers/base.py", line 185, in _get_response
    response = wrapped_callback(request, *callback_args, **callback_kwargs)
  File "/home/ubuntu16-jtg/Envs/env_rampup/local/lib/python2.7/site-packages/django/views/decorators/csrf.py", line 58, in wrapped_view
    return view_func(*args, **kwargs)
  File "/home/ubuntu16-jtg/Envs/env_rampup/local/lib/python2.7/site-packages/rest_framework/viewsets.py", line 103, in view
    return self.dispatch(request, *args, **kwargs)
  File "/home/ubuntu16-jtg/Envs/env_rampup/local/lib/python2.7/site-packages/rest_framework/views.py", line 483, in dispatch
    response = self.handle_exception(exc)
  File "/home/ubuntu16-jtg/Envs/env_rampup/local/lib/python2.7/site-packages/rest_framework/views.py", line 443, in handle_exception
    self.raise_uncaught_exception(exc)
  File "/home/ubuntu16-jtg/Envs/env_rampup/local/lib/python2.7/site-packages/rest_framework/views.py", line 480, in dispatch
    response = handler(request, *args, **kwargs)
  File "/home/ubuntu16-jtg/myWork/office/rampup project/work-flow-api/apps/auth/views.py", line 45, in login
    print(serializer.data.profile_photo.url)
AttributeError: 'ReturnDict' object has no attribute 'profile_photo'
2019-02-11 12:41:41,872 django.request ERROR    Internal Server Error: /api/user/login/
Traceback (most recent call last):
  File "/home/ubuntu16-jtg/Envs/env_rampup/local/lib/python2.7/site-packages/django/core/handlers/exception.py", line 41, in inner
    response = get_response(request)
  File "/home/ubuntu16-jtg/Envs/env_rampup/local/lib/python2.7/site-packages/django/core/handlers/base.py", line 187, in _get_response
    response = self.process_exception_by_middleware(e, request)
  File "/home/ubuntu16-jtg/Envs/env_rampup/local/lib/python2.7/site-packages/django/core/handlers/base.py", line 185, in _get_response
    response = wrapped_callback(request, *callback_args, **callback_kwargs)
  File "/home/ubuntu16-jtg/Envs/env_rampup/local/lib/python2.7/site-packages/django/views/decorators/csrf.py", line 58, in wrapped_view
    return view_func(*args, **kwargs)
  File "/home/ubuntu16-jtg/Envs/env_rampup/local/lib/python2.7/site-packages/rest_framework/viewsets.py", line 103, in view
    return self.dispatch(request, *args, **kwargs)
  File "/home/ubuntu16-jtg/Envs/env_rampup/local/lib/python2.7/site-packages/rest_framework/views.py", line 483, in dispatch
    response = self.handle_exception(exc)
  File "/home/ubuntu16-jtg/Envs/env_rampup/local/lib/python2.7/site-packages/rest_framework/views.py", line 443, in handle_exception
    self.raise_uncaught_exception(exc)
  File "/home/ubuntu16-jtg/Envs/env_rampup/local/lib/python2.7/site-packages/rest_framework/views.py", line 480, in dispatch
    response = handler(request, *args, **kwargs)
  File "/home/ubuntu16-jtg/myWork/office/rampup project/work-flow-api/apps/auth/views.py", line 45, in login
    print(serializer.data.profile_photo)
AttributeError: 'ReturnDict' object has no attribute 'profile_photo'
2019-02-11 12:42:29,411 django.request ERROR    Internal Server Error: /api/user/login/
Traceback (most recent call last):
  File "/home/ubuntu16-jtg/Envs/env_rampup/local/lib/python2.7/site-packages/django/core/handlers/exception.py", line 41, in inner
    response = get_response(request)
  File "/home/ubuntu16-jtg/Envs/env_rampup/local/lib/python2.7/site-packages/django/core/handlers/base.py", line 187, in _get_response
    response = self.process_exception_by_middleware(e, request)
  File "/home/ubuntu16-jtg/Envs/env_rampup/local/lib/python2.7/site-packages/django/core/handlers/base.py", line 185, in _get_response
    response = wrapped_callback(request, *callback_args, **callback_kwargs)
  File "/home/ubuntu16-jtg/Envs/env_rampup/local/lib/python2.7/site-packages/django/views/decorators/csrf.py", line 58, in wrapped_view
    return view_func(*args, **kwargs)
  File "/home/ubuntu16-jtg/Envs/env_rampup/local/lib/python2.7/site-packages/rest_framework/viewsets.py", line 103, in view
    return self.dispatch(request, *args, **kwargs)
  File "/home/ubuntu16-jtg/Envs/env_rampup/local/lib/python2.7/site-packages/rest_framework/views.py", line 483, in dispatch
    response = self.handle_exception(exc)
  File "/home/ubuntu16-jtg/Envs/env_rampup/local/lib/python2.7/site-packages/rest_framework/views.py", line 443, in handle_exception
    self.raise_uncaught_exception(exc)
  File "/home/ubuntu16-jtg/Envs/env_rampup/local/lib/python2.7/site-packages/rest_framework/views.py", line 480, in dispatch
    response = handler(request, *args, **kwargs)
  File "/home/ubuntu16-jtg/myWork/office/rampup project/work-flow-api/apps/auth/views.py", line 45, in login
    print(serializer.data['profile_photo'].url)
AttributeError: 'str' object has no attribute 'url'
2019-02-11 12:44:17,601 django.request WARNING  Not Found: /profile/5dc680f8-9120-48ee-8fa9-8e7cdc13efd3-profile_pawan.png
2019-02-11 12:46:38,362 django.request WARNING  Not Found: /
2019-02-11 12:46:49,528 django.request WARNING  Not Found: /static
2019-02-11 12:47:14,641 django.request WARNING  Not Found: /
2019-02-11 12:47:18,062 django.request WARNING  Not Found: /user/profile/5dc680f8-9120-48ee-8fa9-8e7cdc13efd3-profile_pawan.png
2019-02-11 12:49:52,406 django.request WARNING  Not Found: /user/profile/5dc680f8-9120-48ee-8fa9-8e7cdc13efd3-profile_pawan.png
2019-02-11 12:50:52,633 django.request WARNING  Not Found: /profile/5dc680f8-9120-48ee-8fa9-8e7cdc13efd3-profile_pawan.png
2019-02-11 14:04:56,343 django.request WARNING  Not Found: /http://localhost:8000/user/profile/8ccb6439-e6f4-4ed6-a1aa-7ac748929465-profile_pawan.png
2019-02-11 14:05:18,846 django.request WARNING  Not Found: /http://localhost:8000/user/profile/8ccb6439-e6f4-4ed6-a1aa-7ac748929465-profile_pawan.png
2019-02-11 14:05:23,211 django.request WARNING  Not Found: /http://localhost:8000/user/profile/8ccb6439-e6f4-4ed6-a1aa-7ac748929465-profile_pawan.png
2019-02-11 14:06:21,651 django.request WARNING  Not Found: /http://localhost:8000/user/profile/8ccb6439-e6f4-4ed6-a1aa-7ac748929465-profile_pawan.png
2019-02-11 14:06:21,754 django.request WARNING  Not Found: /http://localhost:8000/http://localhost:8000/user/profile/8ccb6439-e6f4-4ed6-a1aa-7ac748929465-profile_pawan.png
2019-02-11 14:06:32,980 django.request WARNING  Not Found: /http://localhost:8000/user/profile/8ccb6439-e6f4-4ed6-a1aa-7ac748929465-profile_pawan.png
2019-02-11 14:06:51,863 django.request WARNING  Not Found: /http://localhost:8000/user/profile/8ccb6439-e6f4-4ed6-a1aa-7ac748929465-profile_pawan.png
2019-02-11 14:07:03,560 django.request WARNING  Not Found: /http://localhost:8000/user/profile/8ccb6439-e6f4-4ed6-a1aa-7ac748929465-profile_pawan.png
2019-02-11 14:07:03,695 django.request WARNING  Not Found: /http://localhost:8000/http://localhost:8000/user/profile/8ccb6439-e6f4-4ed6-a1aa-7ac748929465-profile_pawan.png
2019-02-11 14:07:07,793 django.request WARNING  Not Found: /http://localhost:8000/user/profile/8ccb6439-e6f4-4ed6-a1aa-7ac748929465-profile_pawan.png
2019-02-11 14:07:13,953 django.request WARNING  Not Found: /http://localhost:8000/user/profile/8ccb6439-e6f4-4ed6-a1aa-7ac748929465-profile_pawan.png
2019-02-11 14:23:00,559 django.request WARNING  Not Found: /http://localhost:8000/user/profile/8ccb6439-e6f4-4ed6-a1aa-7ac748929465-profile_pawan.png
2019-02-11 14:23:00,745 django.request WARNING  Not Found: /http://localhost:8000/user/profile/8ccb6439-e6f4-4ed6-a1aa-7ac748929465-profile_pawan.png
2019-02-11 14:41:38,989 django.request WARNING  Not Found: /user/profile/8ccb6439-e6f4-4ed6-a1aa-7ac748929465-profile_pawan.png
2019-02-11 14:41:39,108 django.request WARNING  Not Found: //media/user/profile/8ccb6439-e6f4-4ed6-a1aa-7ac748929465-profile_pawan.png
2019-02-11 14:41:53,121 django.request WARNING  Not Found: //media/user/profile/8ccb6439-e6f4-4ed6-a1aa-7ac748929465-profile_pawan.png
2019-02-11 14:41:53,293 django.request WARNING  Not Found: /media//media/user/profile/8ccb6439-e6f4-4ed6-a1aa-7ac748929465-profile_pawan.png
2019-02-11 14:41:54,277 django.request WARNING  Not Found: /media//media/user/profile/8ccb6439-e6f4-4ed6-a1aa-7ac748929465-profile_pawan.png
2019-02-11 14:42:01,841 django.request WARNING  Not Found: /media//media/user/profile/8ccb6439-e6f4-4ed6-a1aa-7ac748929465-profile_pawan.png
2019-02-11 14:42:10,594 django.request WARNING  Not Found: /media//media/user/profile/8ccb6439-e6f4-4ed6-a1aa-7ac748929465-profile_pawan.png
2019-02-11 14:42:14,105 django.request WARNING  Not Found: /media/user/profile/8ccb6439-e6f4-4ed6-a1aa-7ac748929465-profile_pawan.png
2019-02-11 14:43:03,868 django.request WARNING  Not Found: /media/user/profile/8ccb6439-e6f4-4ed6-a1aa-7ac748929465-profile_pawan.png
2019-02-11 14:43:04,638 django.request WARNING  Not Found: /media/user/profile/8ccb6439-e6f4-4ed6-a1aa-7ac748929465-profile_pawan.png
2019-02-11 14:43:06,191 django.request WARNING  Not Found: /media/user/profile/8ccb6439-e6f4-4ed6-a1aa-7ac748929465-profile_pawan.png
2019-02-11 14:43:29,170 django.request WARNING  Not Found: /media/user/profile/8ccb6439-e6f4-4ed6-a1aa-7ac748929465-profile_pawan.png
2019-02-11 14:43:29,778 django.request WARNING  Not Found: /media/user/profile/8ccb6439-e6f4-4ed6-a1aa-7ac748929465-profile_pawan.png
2019-02-11 14:43:30,159 django.request WARNING  Not Found: /media/user/profile/8ccb6439-e6f4-4ed6-a1aa-7ac748929465-profile_pawan.png
2019-02-11 14:43:30,531 django.request WARNING  Not Found: /media/user/profile/8ccb6439-e6f4-4ed6-a1aa-7ac748929465-profile_pawan.png
2019-02-11 14:43:30,875 django.request WARNING  Not Found: /media/user/profile/8ccb6439-e6f4-4ed6-a1aa-7ac748929465-profile_pawan.png
2019-02-11 14:43:31,276 django.request WARNING  Not Found: /media/user/profile/8ccb6439-e6f4-4ed6-a1aa-7ac748929465-profile_pawan.png
2019-02-11 14:43:55,835 django.request WARNING  Not Found: /media/user/profile/8ccb6439-e6f4-4ed6-a1aa-7ac748929465-profile_pawan.png
2019-02-11 14:51:29,660 django.request WARNING  Not Found: /media/user/profile/8ccb6439-e6f4-4ed6-a1aa-7ac748929465-profile_pawan.png
2019-02-11 14:51:30,457 django.request WARNING  Not Found: /media/user/profile/8ccb6439-e6f4-4ed6-a1aa-7ac748929465-profile_pawan.png
2019-02-11 14:52:01,820 django.request WARNING  Not Found: /media/user/profile/8ccb6439-e6f4-4ed6-a1aa-7ac748929465-profile_pawan.png
2019-02-11 14:52:21,294 django.request WARNING  Not Found: /media/user/profile/8ccb6439-e6f4-4ed6-a1aa-7ac748929465-profile_pawan.png
2019-02-11 14:52:21,780 django.request WARNING  Not Found: /media/user/profile/8ccb6439-e6f4-4ed6-a1aa-7ac748929465-profile_pawan.png
2019-02-11 14:57:19,850 django.request WARNING  Not Found: /media//media/user/profile/8ccb6439-e6f4-4ed6-a1aa-7ac748929465-profile_pawan.png
