2019-02-07 21:23:29,525 django.request WARNING  Not Found: /api/employee/my-company/
2019-02-07 23:54:38,727 django.request WARNING  Not Found: /api//company/undefined/
2019-02-07 23:54:43,567 django.request WARNING  Not Found: /api//company/undefined/
2019-02-08 06:10:46,660 django.request WARNING  Not Found: /favicon.ico
2019-02-08 07:15:31,125 django.request WARNING  Not Found: /
2019-02-08 07:15:31,594 django.request WARNING  Not Found: /favicon.ico
2019-02-08 07:22:30,609 django.request WARNING  Not Found: /api/employee/my-company/
2019-02-08 07:25:06,870 django.request WARNING  Not Found: /api//company/undefined/
2019-02-08 07:33:23,941 apps.auth.models DEBUG    reset token 53o-be6ffb2a6bc68b013a92--10
2019-02-08 09:37:14,693 apps.auth.models INFO     Verification mail send to akhileshrao19@gmail.com
2019-02-08 09:38:54,252 apps.company.models INFO     creation mail send to test@t.com
2019-02-08 09:38:55,344 apps.company.models INFO     creation mail send to akhileshrao19@gmail.com
2019-02-08 09:40:53,961 apps.company.models INFO     Invite mail send to akhileshrao19@gmail.com
2019-02-08 09:55:41,588 apps.auth.models DEBUG    reset token 53o-2a1bdf89051ef46ee7d9--1
2019-02-08 10:06:10,876 django.request ERROR    Internal Server Error: /api/company/invite-employee/
Traceback (most recent call last):
  File "/home/akhilesh/.envs/wf/local/lib/python2.7/site-packages/django/core/handlers/exception.py", line 41, in inner
    response = get_response(request)
  File "/home/akhilesh/.envs/wf/local/lib/python2.7/site-packages/django/core/handlers/base.py", line 187, in _get_response
    response = self.process_exception_by_middleware(e, request)
  File "/home/akhilesh/.envs/wf/local/lib/python2.7/site-packages/django/core/handlers/base.py", line 185, in _get_response
    response = wrapped_callback(request, *callback_args, **callback_kwargs)
  File "/home/akhilesh/.envs/wf/local/lib/python2.7/site-packages/django/views/decorators/csrf.py", line 58, in wrapped_view
    return view_func(*args, **kwargs)
  File "/home/akhilesh/.envs/wf/local/lib/python2.7/site-packages/rest_framework/viewsets.py", line 103, in view
    return self.dispatch(request, *args, **kwargs)
  File "/home/akhilesh/.envs/wf/local/lib/python2.7/site-packages/rest_framework/views.py", line 483, in dispatch
    response = self.handle_exception(exc)
  File "/home/akhilesh/.envs/wf/local/lib/python2.7/site-packages/rest_framework/views.py", line 443, in handle_exception
    self.raise_uncaught_exception(exc)
  File "/home/akhilesh/.envs/wf/local/lib/python2.7/site-packages/rest_framework/views.py", line 480, in dispatch
    response = handler(request, *args, **kwargs)
  File "/home/akhilesh/Documents/workflow_platform/apps/company/views.py", line 139, in invite_employee
    serializer.save()
  File "/home/akhilesh/.envs/wf/local/lib/python2.7/site-packages/rest_framework/serializers.py", line 214, in save
    self.instance = self.create(validated_data)
  File "/home/akhilesh/Documents/workflow_platform/apps/company/serializers.py", line 233, in create
    user = self.get_user_instance(validated_data)
  File "/home/akhilesh/Documents/workflow_platform/apps/company/serializers.py", line 229, in get_user_instance
    **user
  File "/home/akhilesh/Documents/workflow_platform/apps/auth/models.py", line 53, in create_user
    return self._create_user(email, password, **extra_fields)
  File "/home/akhilesh/Documents/workflow_platform/apps/auth/models.py", line 42, in _create_user
    user = self.model(email=email, **extra_fields)
  File "/home/akhilesh/.envs/wf/local/lib/python2.7/site-packages/django/contrib/auth/base_user.py", line 68, in __init__
    super(AbstractBaseUser, self).__init__(*args, **kwargs)
  File "/home/akhilesh/.envs/wf/local/lib/python2.7/site-packages/django/db/models/base.py", line 571, in __init__
    raise TypeError("'%s' is an invalid keyword argument for this function" % list(kwargs)[0])
TypeError: 'is_admin' is an invalid keyword argument for this function
2019-02-08 10:06:51,253 apps.company.models INFO     Invite mail send to parul@pokemail.net
2019-02-08 10:08:21,079 apps.company.models INFO     Invite mail send to zigzag@pokemail.net
2019-02-08 10:09:20,614 apps.company.models INFO     Invite mail send to zigzag@pokemail.net
2019-02-08 10:12:22,999 django.request ERROR    Internal Server Error: /admin/company/usercompany/34/change/
Traceback (most recent call last):
  File "/home/akhilesh/.envs/wf/local/lib/python2.7/site-packages/django/core/handlers/exception.py", line 41, in inner
    response = get_response(request)
  File "/home/akhilesh/.envs/wf/local/lib/python2.7/site-packages/django/core/handlers/base.py", line 187, in _get_response
    response = self.process_exception_by_middleware(e, request)
  File "/home/akhilesh/.envs/wf/local/lib/python2.7/site-packages/django/core/handlers/base.py", line 185, in _get_response
    response = wrapped_callback(request, *callback_args, **callback_kwargs)
  File "/home/akhilesh/.envs/wf/local/lib/python2.7/site-packages/django/contrib/admin/options.py", line 551, in wrapper
    return self.admin_site.admin_view(view)(*args, **kwargs)
  File "/home/akhilesh/.envs/wf/local/lib/python2.7/site-packages/django/utils/decorators.py", line 149, in _wrapped_view
    response = view_func(request, *args, **kwargs)
  File "/home/akhilesh/.envs/wf/local/lib/python2.7/site-packages/django/views/decorators/cache.py", line 57, in _wrapped_view_func
    response = view_func(request, *args, **kwargs)
  File "/home/akhilesh/.envs/wf/local/lib/python2.7/site-packages/django/contrib/admin/sites.py", line 224, in inner
    return view(request, *args, **kwargs)
  File "/home/akhilesh/.envs/wf/local/lib/python2.7/site-packages/django/contrib/admin/options.py", line 1511, in change_view
    return self.changeform_view(request, object_id, form_url, extra_context)
  File "/home/akhilesh/.envs/wf/local/lib/python2.7/site-packages/django/utils/decorators.py", line 67, in _wrapper
    return bound_func(*args, **kwargs)
  File "/home/akhilesh/.envs/wf/local/lib/python2.7/site-packages/django/utils/decorators.py", line 149, in _wrapped_view
    response = view_func(request, *args, **kwargs)
  File "/home/akhilesh/.envs/wf/local/lib/python2.7/site-packages/django/utils/decorators.py", line 63, in bound_func
    return func.__get__(self, type(self))(*args2, **kwargs2)
  File "/home/akhilesh/.envs/wf/local/lib/python2.7/site-packages/django/contrib/admin/options.py", line 1408, in changeform_view
    return self._changeform_view(request, object_id, form_url, extra_context)
  File "/home/akhilesh/.envs/wf/local/lib/python2.7/site-packages/django/contrib/admin/options.py", line 1448, in _changeform_view
    self.save_model(request, new_object, form, not add)
  File "/home/akhilesh/.envs/wf/local/lib/python2.7/site-packages/django/contrib/admin/options.py", line 979, in save_model
    obj.save()
  File "/home/akhilesh/.envs/wf/local/lib/python2.7/site-packages/django/db/models/base.py", line 806, in save
    force_update=force_update, update_fields=update_fields)
  File "/home/akhilesh/.envs/wf/local/lib/python2.7/site-packages/django/db/models/base.py", line 836, in save_base
    updated = self._save_table(raw, cls, force_insert, force_update, using, update_fields)
  File "/home/akhilesh/.envs/wf/local/lib/python2.7/site-packages/django/db/models/base.py", line 903, in _save_table
    forced_update)
  File "/home/akhilesh/.envs/wf/local/lib/python2.7/site-packages/django/db/models/base.py", line 953, in _do_update
    return filtered._update(values) > 0
  File "/home/akhilesh/.envs/wf/local/lib/python2.7/site-packages/django/db/models/query.py", line 661, in _update
    return query.get_compiler(self.db).execute_sql(CURSOR)
  File "/home/akhilesh/.envs/wf/local/lib/python2.7/site-packages/django/db/models/sql/compiler.py", line 1191, in execute_sql
    cursor = super(SQLUpdateCompiler, self).execute_sql(result_type)
  File "/home/akhilesh/.envs/wf/local/lib/python2.7/site-packages/django/db/models/sql/compiler.py", line 876, in execute_sql
    cursor.execute(sql, params)
  File "/home/akhilesh/.envs/wf/local/lib/python2.7/site-packages/django/db/backends/utils.py", line 80, in execute
    return super(CursorDebugWrapper, self).execute(sql, params)
  File "/home/akhilesh/.envs/wf/local/lib/python2.7/site-packages/django/db/backends/utils.py", line 65, in execute
    return self.cursor.execute(sql, params)
  File "/home/akhilesh/.envs/wf/local/lib/python2.7/site-packages/django/db/utils.py", line 94, in __exit__
    six.reraise(dj_exc_type, dj_exc_value, traceback)
  File "/home/akhilesh/.envs/wf/local/lib/python2.7/site-packages/django/db/backends/utils.py", line 65, in execute
    return self.cursor.execute(sql, params)
IntegrityError: duplicate key value violates unique constraint "company_use_user_id_a07d1a_partial"
DETAIL:  Key (user_id, company_id)=(36, 2) already exists.

2019-02-08 10:12:44,409 django.request ERROR    Internal Server Error: /admin/company/usercompany/34/change/
Traceback (most recent call last):
  File "/home/akhilesh/.envs/wf/local/lib/python2.7/site-packages/django/core/handlers/exception.py", line 41, in inner
    response = get_response(request)
  File "/home/akhilesh/.envs/wf/local/lib/python2.7/site-packages/django/core/handlers/base.py", line 187, in _get_response
    response = self.process_exception_by_middleware(e, request)
  File "/home/akhilesh/.envs/wf/local/lib/python2.7/site-packages/django/core/handlers/base.py", line 185, in _get_response
    response = wrapped_callback(request, *callback_args, **callback_kwargs)
  File "/home/akhilesh/.envs/wf/local/lib/python2.7/site-packages/django/contrib/admin/options.py", line 551, in wrapper
    return self.admin_site.admin_view(view)(*args, **kwargs)
  File "/home/akhilesh/.envs/wf/local/lib/python2.7/site-packages/django/utils/decorators.py", line 149, in _wrapped_view
    response = view_func(request, *args, **kwargs)
  File "/home/akhilesh/.envs/wf/local/lib/python2.7/site-packages/django/views/decorators/cache.py", line 57, in _wrapped_view_func
    response = view_func(request, *args, **kwargs)
  File "/home/akhilesh/.envs/wf/local/lib/python2.7/site-packages/django/contrib/admin/sites.py", line 224, in inner
    return view(request, *args, **kwargs)
  File "/home/akhilesh/.envs/wf/local/lib/python2.7/site-packages/django/contrib/admin/options.py", line 1511, in change_view
    return self.changeform_view(request, object_id, form_url, extra_context)
  File "/home/akhilesh/.envs/wf/local/lib/python2.7/site-packages/django/utils/decorators.py", line 67, in _wrapper
    return bound_func(*args, **kwargs)
  File "/home/akhilesh/.envs/wf/local/lib/python2.7/site-packages/django/utils/decorators.py", line 149, in _wrapped_view
    response = view_func(request, *args, **kwargs)
  File "/home/akhilesh/.envs/wf/local/lib/python2.7/site-packages/django/utils/decorators.py", line 63, in bound_func
    return func.__get__(self, type(self))(*args2, **kwargs2)
  File "/home/akhilesh/.envs/wf/local/lib/python2.7/site-packages/django/contrib/admin/options.py", line 1408, in changeform_view
    return self._changeform_view(request, object_id, form_url, extra_context)
  File "/home/akhilesh/.envs/wf/local/lib/python2.7/site-packages/django/contrib/admin/options.py", line 1448, in _changeform_view
    self.save_model(request, new_object, form, not add)
  File "/home/akhilesh/.envs/wf/local/lib/python2.7/site-packages/django/contrib/admin/options.py", line 979, in save_model
    obj.save()
  File "/home/akhilesh/.envs/wf/local/lib/python2.7/site-packages/django/db/models/base.py", line 806, in save
    force_update=force_update, update_fields=update_fields)
  File "/home/akhilesh/.envs/wf/local/lib/python2.7/site-packages/django/db/models/base.py", line 836, in save_base
    updated = self._save_table(raw, cls, force_insert, force_update, using, update_fields)
  File "/home/akhilesh/.envs/wf/local/lib/python2.7/site-packages/django/db/models/base.py", line 903, in _save_table
    forced_update)
  File "/home/akhilesh/.envs/wf/local/lib/python2.7/site-packages/django/db/models/base.py", line 953, in _do_update
    return filtered._update(values) > 0
  File "/home/akhilesh/.envs/wf/local/lib/python2.7/site-packages/django/db/models/query.py", line 661, in _update
    return query.get_compiler(self.db).execute_sql(CURSOR)
  File "/home/akhilesh/.envs/wf/local/lib/python2.7/site-packages/django/db/models/sql/compiler.py", line 1191, in execute_sql
    cursor = super(SQLUpdateCompiler, self).execute_sql(result_type)
  File "/home/akhilesh/.envs/wf/local/lib/python2.7/site-packages/django/db/models/sql/compiler.py", line 876, in execute_sql
    cursor.execute(sql, params)
  File "/home/akhilesh/.envs/wf/local/lib/python2.7/site-packages/django/db/backends/utils.py", line 80, in execute
    return super(CursorDebugWrapper, self).execute(sql, params)
  File "/home/akhilesh/.envs/wf/local/lib/python2.7/site-packages/django/db/backends/utils.py", line 65, in execute
    return self.cursor.execute(sql, params)
  File "/home/akhilesh/.envs/wf/local/lib/python2.7/site-packages/django/db/utils.py", line 94, in __exit__
    six.reraise(dj_exc_type, dj_exc_value, traceback)
  File "/home/akhilesh/.envs/wf/local/lib/python2.7/site-packages/django/db/backends/utils.py", line 65, in execute
    return self.cursor.execute(sql, params)
IntegrityError: duplicate key value violates unique constraint "company_use_user_id_a07d1a_partial"
DETAIL:  Key (user_id, company_id)=(36, 2) already exists.

2019-02-08 10:28:02,132 django.request ERROR    Internal Server Error: /api/company/new-company/
Traceback (most recent call last):
  File "/home/akhilesh/.envs/wf/local/lib/python2.7/site-packages/django/core/handlers/exception.py", line 41, in inner
    response = get_response(request)
  File "/home/akhilesh/.envs/wf/local/lib/python2.7/site-packages/django/core/handlers/base.py", line 187, in _get_response
    response = self.process_exception_by_middleware(e, request)
  File "/home/akhilesh/.envs/wf/local/lib/python2.7/site-packages/django/core/handlers/base.py", line 185, in _get_response
    response = wrapped_callback(request, *callback_args, **callback_kwargs)
  File "/home/akhilesh/.envs/wf/local/lib/python2.7/site-packages/django/views/decorators/csrf.py", line 58, in wrapped_view
    return view_func(*args, **kwargs)
  File "/home/akhilesh/.envs/wf/local/lib/python2.7/site-packages/rest_framework/viewsets.py", line 103, in view
    return self.dispatch(request, *args, **kwargs)
  File "/home/akhilesh/.envs/wf/local/lib/python2.7/site-packages/rest_framework/views.py", line 483, in dispatch
    response = self.handle_exception(exc)
  File "/home/akhilesh/.envs/wf/local/lib/python2.7/site-packages/rest_framework/views.py", line 443, in handle_exception
    self.raise_uncaught_exception(exc)
  File "/home/akhilesh/.envs/wf/local/lib/python2.7/site-packages/rest_framework/views.py", line 480, in dispatch
    response = handler(request, *args, **kwargs)
  File "/home/akhilesh/Documents/workflow_platform/apps/company/views.py", line 66, in new_company
    serializer.save()
  File "/home/akhilesh/.envs/wf/local/lib/python2.7/site-packages/rest_framework/serializers.py", line 214, in save
    self.instance = self.create(validated_data)
  File "/home/akhilesh/Documents/workflow_platform/apps/company/serializers.py", line 153, in create
    company.company_create_mail()
AttributeError: 'Company' object has no attribute 'company_create_mail'
2019-02-08 10:28:52,590 apps.company.models INFO     Invite mail send to zigzag@pokemail.net
2019-02-08 10:37:16,999 apps.company.models INFO     Invite mail send to zigzag@pokemail.net
2019-02-08 10:38:36,232 apps.company.models INFO     Invite mail send to parul@pokemail.net
2019-02-08 12:03:25,487 apps.auth.models DEBUG    reset token 53o-69aabe2313d5cf9b448f--37
2019-02-08 12:08:02,461 apps.auth.serializers DEBUG    reset request for pawan.bansal@joshtechnology.com
2019-02-08 12:08:02,461 apps.auth.models DEBUG    reset token 53o-69aabe2313d5cf9b448f--37
2019-02-08 12:08:27,168 apps.auth.serializers DEBUG    reset request for pawan.bansal@joshtechnology.com
2019-02-08 12:08:27,168 apps.auth.models DEBUG    reset token 53o-69aabe2313d5cf9b448f--37
